[2024-07-05 17:28:30,475] DEBUG (connectionpool.py:244) Starting new HTTP connection (1): 10.251.52.102:18080
[2024-07-05 17:28:31,532] DEBUG (connectionpool.py:546) http://10.251.52.102:18080 "POST /jax/api/v1/pipeline/jax_MSB.ALP_TRACELOG_sq/stage HTTP/1.1" 401 None
[2024-07-05 17:28:31,532] ERROR (创建解析任务和存储任务和中台任务.py:41) Expecting value: line 1 column 1 (char 0)
Traceback (most recent call last):
  File "C:\Users\Farben\AppData\Local\Programs\Python\Python38-32\lib\site-packages\requests\models.py", line 971, in json
    return complexjson.loads(self.text, **kwargs)
  File "C:\Users\Farben\AppData\Local\Programs\Python\Python38-32\lib\json\__init__.py", line 357, in loads
    return _default_decoder.decode(s)
  File "C:\Users\Farben\AppData\Local\Programs\Python\Python38-32\lib\json\decoder.py", line 337, in decode
    obj, end = self.raw_decode(s, idx=_w(s, 0).end())
  File "C:\Users\Farben\AppData\Local\Programs\Python\Python38-32\lib\json\decoder.py", line 355, in raw_decode
    raise JSONDecodeError("Expecting value", s, err.value) from None
json.decoder.JSONDecodeError: Expecting value: line 1 column 1 (char 0)

During handling of the above exception, another exception occurred:

Traceback (most recent call last):
  File "e:/Deskop/People/script/python/script/Aiops/创建解析任务和存储任务和中台任务.py", line 38, in do_request
    res = res.json()
  File "C:\Users\Farben\AppData\Local\Programs\Python\Python38-32\lib\site-packages\requests\models.py", line 975, in json
    raise RequestsJSONDecodeError(e.msg, e.doc, e.pos)
requests.exceptions.JSONDecodeError: Expecting value: line 1 column 1 (char 0)
[2024-07-05 17:30:42,117] DEBUG (connectionpool.py:244) Starting new HTTP connection (1): 10.251.52.102:18080
[2024-07-05 17:30:42,190] DEBUG (connectionpool.py:546) http://10.251.52.102:18080 "POST /jax/api/v1/pipeline/jax_MSB.ALP_TRACELOG_sq/stage HTTP/1.1" 401 None
[2024-07-05 17:30:42,190] ERROR (创建解析任务和存储任务和中台任务.py:41) Expecting value: line 1 column 1 (char 0)
Traceback (most recent call last):
  File "C:\Users\Farben\AppData\Local\Programs\Python\Python38-32\lib\site-packages\requests\models.py", line 971, in json
    return complexjson.loads(self.text, **kwargs)
  File "C:\Users\Farben\AppData\Local\Programs\Python\Python38-32\lib\json\__init__.py", line 357, in loads
    return _default_decoder.decode(s)
  File "C:\Users\Farben\AppData\Local\Programs\Python\Python38-32\lib\json\decoder.py", line 337, in decode
    obj, end = self.raw_decode(s, idx=_w(s, 0).end())
  File "C:\Users\Farben\AppData\Local\Programs\Python\Python38-32\lib\json\decoder.py", line 355, in raw_decode
    raise JSONDecodeError("Expecting value", s, err.value) from None
json.decoder.JSONDecodeError: Expecting value: line 1 column 1 (char 0)

During handling of the above exception, another exception occurred:

Traceback (most recent call last):
  File "e:/Deskop/People/script/python/script/Aiops/创建解析任务和存储任务和中台任务.py", line 38, in do_request
    res = res.json()
  File "C:\Users\Farben\AppData\Local\Programs\Python\Python38-32\lib\site-packages\requests\models.py", line 975, in json
    raise RequestsJSONDecodeError(e.msg, e.doc, e.pos)
requests.exceptions.JSONDecodeError: Expecting value: line 1 column 1 (char 0)
[2024-07-05 17:36:33,294] DEBUG (connectionpool.py:244) Starting new HTTP connection (1): 10.251.52.102:18080
[2024-07-05 17:36:33,349] DEBUG (connectionpool.py:546) http://10.251.52.102:18080 "POST /jax/api/v1/pipeline/jax_MSB.ALP_TRACELOG_sq/stage HTTP/1.1" 401 None
[2024-07-05 17:36:33,349] ERROR (创建解析任务和存储任务和中台任务.py:41) Expecting value: line 1 column 1 (char 0)
Traceback (most recent call last):
  File "c:\Users\Farben\AppData\Local\Programs\Python\Python38-32\lib\site-packages\requests\models.py", line 971, in json
    return complexjson.loads(self.text, **kwargs)
  File "c:\Users\Farben\AppData\Local\Programs\Python\Python38-32\lib\json\__init__.py", line 357, in loads
    return _default_decoder.decode(s)
  File "c:\Users\Farben\AppData\Local\Programs\Python\Python38-32\lib\json\decoder.py", line 337, in decode
    obj, end = self.raw_decode(s, idx=_w(s, 0).end())
  File "c:\Users\Farben\AppData\Local\Programs\Python\Python38-32\lib\json\decoder.py", line 355, in raw_decode
    raise JSONDecodeError("Expecting value", s, err.value) from None
json.decoder.JSONDecodeError: Expecting value: line 1 column 1 (char 0)

During handling of the above exception, another exception occurred:

Traceback (most recent call last):
  File "e:\Deskop\People\script\python\script\Aiops\创建解析任务和存储任务和中台任务.py", line 38, in do_request
    res = res.json()
  File "c:\Users\Farben\AppData\Local\Programs\Python\Python38-32\lib\site-packages\requests\models.py", line 975, in json
    raise RequestsJSONDecodeError(e.msg, e.doc, e.pos)
requests.exceptions.JSONDecodeError: Expecting value: line 1 column 1 (char 0)
[2024-07-05 17:39:46,803] DEBUG (connectionpool.py:244) Starting new HTTP connection (1): 10.251.52.102:18080
[2024-07-05 17:39:46,822] DEBUG (connectionpool.py:546) http://10.251.52.102:18080 "POST /jax/api/v1/pipeline/jax_MSB.ALP_TRACELOG_sq/stage HTTP/1.1" 401 None
[2024-07-05 17:39:46,823] ERROR (创建解析任务和存储任务和中台任务.py:41) Expecting value: line 1 column 1 (char 0)
Traceback (most recent call last):
  File "C:\Users\Farben\AppData\Local\Programs\Python\Python38-32\lib\site-packages\requests\models.py", line 971, in json
    return complexjson.loads(self.text, **kwargs)
  File "C:\Users\Farben\AppData\Local\Programs\Python\Python38-32\lib\json\__init__.py", line 357, in loads
    return _default_decoder.decode(s)
  File "C:\Users\Farben\AppData\Local\Programs\Python\Python38-32\lib\json\decoder.py", line 337, in decode
    obj, end = self.raw_decode(s, idx=_w(s, 0).end())
  File "C:\Users\Farben\AppData\Local\Programs\Python\Python38-32\lib\json\decoder.py", line 355, in raw_decode
    raise JSONDecodeError("Expecting value", s, err.value) from None
json.decoder.JSONDecodeError: Expecting value: line 1 column 1 (char 0)

During handling of the above exception, another exception occurred:

Traceback (most recent call last):
  File "e:/Deskop/People/script/python/script/Aiops/创建解析任务和存储任务和中台任务.py", line 38, in do_request
    res = res.json()
  File "C:\Users\Farben\AppData\Local\Programs\Python\Python38-32\lib\site-packages\requests\models.py", line 975, in json
    raise RequestsJSONDecodeError(e.msg, e.doc, e.pos)
requests.exceptions.JSONDecodeError: Expecting value: line 1 column 1 (char 0)
[2024-07-05 17:40:31,508] DEBUG (connectionpool.py:244) Starting new HTTP connection (1): 10.251.52.102:18080
[2024-07-05 17:40:31,560] DEBUG (connectionpool.py:546) http://10.251.52.102:18080 "POST /jax/api/v1/pipeline/jax_MSB.ALP_TRACELOG_sq/stage HTTP/1.1" 401 None
[2024-07-05 17:40:37,261] DEBUG (api.py:78) Encoding detection on empty bytes, assuming utf_8 intention.
[2024-07-05 17:41:58,721] DEBUG (connectionpool.py:244) Starting new HTTP connection (1): 10.251.52.102:18080
[2024-07-05 17:41:58,769] DEBUG (connectionpool.py:546) http://10.251.52.102:18080 "POST /jax/api/v1/pipeline/jax_MSB.ALP_TRACELOG_sq/stage HTTP/1.1" 200 None
[2024-07-05 17:41:58,774] ERROR (创建解析任务和存储任务和中台任务.py:345) 创建jax_MSB.ALP_TRACELOG_sq中台任务执行失败：名称非法（只能使用字母数字-_）
[2024-07-05 17:41:58,774] DEBUG (connectionpool.py:244) Starting new HTTP connection (1): 10.251.52.102:18080
[2024-07-05 17:41:58,879] DEBUG (connectionpool.py:546) http://10.251.52.102:18080 "POST /logAnalysis/api/itoa/dataset/stream HTTP/1.1" 200 None
[2024-07-05 17:41:58,919] INFO (创建解析任务和存储任务和中台任务.py:234) 创建['APP_MSB.ALP_TRACELOG_ETL']解析任务成功：success, task_id:313103640457216
[2024-07-05 17:41:58,924] DEBUG (connectionpool.py:244) Starting new HTTP connection (1): 10.251.52.102:18080
[2024-07-05 17:42:02,674] DEBUG (connectionpool.py:546) http://10.251.52.102:18080 "POST /logAnalysis/api/itoa/dataset/storageOutPut HTTP/1.1" 200 None
[2024-07-05 17:42:02,674] INFO (创建解析任务和存储任务和中台任务.py:99) 创建['APP_MSB.ALP_TRACELOG_ETL']存储任务成功：添加成功
[2024-07-05 17:42:02,684] DEBUG (connectionpool.py:244) Starting new HTTP connection (1): 10.251.52.102:18080
[2024-07-05 17:42:02,764] DEBUG (connectionpool.py:546) http://10.251.52.102:18080 "POST /jax/api/v1/pipeline/jax_MSB.ALP_TRACELOG_zj/stage HTTP/1.1" 200 None
[2024-07-05 17:42:02,764] ERROR (创建解析任务和存储任务和中台任务.py:345) 创建jax_MSB.ALP_TRACELOG_zj中台任务执行失败：名称非法（只能使用字母数字-_）
[2024-07-05 17:42:02,764] DEBUG (connectionpool.py:244) Starting new HTTP connection (1): 10.251.52.102:18080
[2024-07-05 17:42:02,854] DEBUG (connectionpool.py:546) http://10.251.52.102:18080 "POST /logAnalysis/api/itoa/dataset/stream HTTP/1.1" 200 None
[2024-07-05 17:42:02,857] INFO (创建解析任务和存储任务和中台任务.py:234) 创建['APP_MSB.ALP_TRACELOG_ETL']解析任务成功：success, task_id:313103656689664
[2024-07-05 17:42:02,859] DEBUG (connectionpool.py:244) Starting new HTTP connection (1): 10.251.52.102:18080
[2024-07-05 17:42:05,965] DEBUG (connectionpool.py:546) http://10.251.52.102:18080 "POST /logAnalysis/api/itoa/dataset/storageOutPut HTTP/1.1" 200 None
[2024-07-05 17:42:05,965] INFO (创建解析任务和存储任务和中台任务.py:99) 创建['APP_MSB.ALP_TRACELOG_ETL']存储任务成功：添加成功
[2024-07-05 17:49:06,509] DEBUG (connectionpool.py:244) Starting new HTTP connection (1): 10.251.52.102:18080
[2024-07-05 17:49:06,577] DEBUG (connectionpool.py:546) http://10.251.52.102:18080 "POST /jax/api/v1/pipeline/jax_MSB-ALP_TRACELOG_sq/stage HTTP/1.1" 200 None
[2024-07-05 17:49:06,577] INFO (创建解析任务和存储任务和中台任务.py:343) 创建jax_MSB-ALP_TRACELOG_sq中台任务成功：成功
[2024-07-05 17:49:06,577] DEBUG (connectionpool.py:244) Starting new HTTP connection (1): 10.251.52.102:18080
[2024-07-05 17:49:06,911] DEBUG (connectionpool.py:546) http://10.251.52.102:18080 "POST /logAnalysis/api/itoa/dataset/stream HTTP/1.1" 200 None
[2024-07-05 17:49:06,911] INFO (创建解析任务和存储任务和中台任务.py:234) 创建['APP_MSB.ALP_TRACELOG_ETL']解析任务成功：success, task_id:313105392762880
[2024-07-05 17:53:20,501] DEBUG (connectionpool.py:244) Starting new HTTP connection (1): 10.251.52.102:18080
[2024-07-05 17:53:20,567] DEBUG (connectionpool.py:546) http://10.251.52.102:18080 "POST /jax/api/v1/pipeline/jax_MSB-ALP_TRACELOG_sq/stage HTTP/1.1" 200 None
[2024-07-05 17:53:20,568] INFO (创建解析任务和存储任务和中台任务.py:343) 创建jax_MSB-ALP_TRACELOG_sq中台任务成功：成功
[2024-07-05 17:53:20,568] DEBUG (connectionpool.py:244) Starting new HTTP connection (1): 10.251.52.102:18080
[2024-07-05 17:53:20,634] DEBUG (connectionpool.py:546) http://10.251.52.102:18080 "POST /logAnalysis/api/itoa/dataset/stream HTTP/1.1" 200 None
[2024-07-05 17:53:20,634] INFO (创建解析任务和存储任务和中台任务.py:234) 创建['APP_MSB.ALP_TRACELOG_ETL']解析任务成功：success, task_id:313106432880640
[2024-07-05 17:53:20,634] DEBUG (connectionpool.py:244) Starting new HTTP connection (1): 10.251.52.102:18080
[2024-07-05 17:53:23,231] DEBUG (connectionpool.py:546) http://10.251.52.102:18080 "POST /logAnalysis/api/itoa/dataset/storageOutPut HTTP/1.1" 200 None
[2024-07-05 17:53:23,231] INFO (创建解析任务和存储任务和中台任务.py:99) 创建['APP_MSB.ALP_TRACELOG_ETL']存储任务成功：添加成功
[2024-07-05 17:53:23,231] DEBUG (connectionpool.py:244) Starting new HTTP connection (1): 10.251.52.102:18080
[2024-07-05 17:53:23,284] DEBUG (connectionpool.py:546) http://10.251.52.102:18080 "POST /jax/api/v1/pipeline/jax_MSB-ALP_TRACELOG_zj/stage HTTP/1.1" 200 None
[2024-07-05 17:53:23,284] INFO (创建解析任务和存储任务和中台任务.py:343) 创建jax_MSB-ALP_TRACELOG_zj中台任务成功：成功
[2024-07-05 17:53:23,286] DEBUG (connectionpool.py:244) Starting new HTTP connection (1): 10.251.52.102:18080
[2024-07-05 17:53:23,373] DEBUG (connectionpool.py:546) http://10.251.52.102:18080 "POST /logAnalysis/api/itoa/dataset/stream HTTP/1.1" 200 None
[2024-07-05 17:53:23,374] INFO (创建解析任务和存储任务和中台任务.py:234) 创建['APP_MSB.ALP_TRACELOG_ETL']解析任务成功：success, task_id:313106444001280
[2024-07-05 17:53:23,375] DEBUG (connectionpool.py:244) Starting new HTTP connection (1): 10.251.52.102:18080
[2024-07-05 17:53:26,501] DEBUG (connectionpool.py:546) http://10.251.52.102:18080 "POST /logAnalysis/api/itoa/dataset/storageOutPut HTTP/1.1" 200 None
[2024-07-05 17:53:26,501] INFO (创建解析任务和存储任务和中台任务.py:99) 创建['APP_MSB.ALP_TRACELOG_ETL']存储任务成功：添加成功
